<!DOCTYPE html>
<html xmlns="http://www.w3.org/1999/xhtml" lang="" xml:lang="">
<head>
  <meta charset="utf-8" />
  <meta name="generator" content="pandoc" />
  <meta name="viewport" content="width=device-width, initial-scale=1.0, user-scalable=yes" />
  <title>try...catch</title>
  <style type="text/css">
      code{white-space: pre-wrap;}
      span.smallcaps{font-variant: small-caps;}
      span.underline{text-decoration: underline;}
      div.column{display: inline-block; vertical-align: top; width: 50%;}
  </style>
</head>
<body>
<h1 id="trycatch">try…catch</h1>
<p>The <code>try...catch</code> statement marks a block of statements to try and specifies a response should an exception be thrown.</p>
<h2 id="syntax">Syntax</h2>
<pre><code>try {
  try_statements
}
catch (exception_var) {
  catch_statements
}
finally {
  finally_statements
}</code></pre>
<p><code>try_statements</code><br />
The statements to be executed.</p>
<p><code>catch_statements</code><br />
Statement that is executed if an exception is thrown in the <code>try</code>-block.</p>
<p><code>exception_var</code><br />
An optional identifier to hold an exception object for the associated <code>catch</code>-block.</p>
<p><code>finally_statements</code><br />
Statements that are executed after the <code>try</code> statement completes. These statements execute regardless of whether an exception was thrown or caught.</p>
<h2 id="description">Description</h2>
<p>The <code>try</code> statement consists of a <code>try</code>-block, which contains one or more statements. <code>{}</code> must always be used, even for single statements. At least one <code>catch</code>-block, or a <code>finally</code>-block, must be present. This gives us three forms for the <code>try</code> statement:</p>
<ul>
<li><code>try...catch</code></li>
<li><code>try...finally</code></li>
<li><code>try...catch...finally</code></li>
</ul>
<p>A <code>catch</code>-block contains statements that specify what to do if an exception is thrown in the <code>try</code>-block. If any statement within the <code>try</code>-block (or in a function called from within the <code>try</code>-block) throws an exception, control is immediately shifted to the <code>catch</code>-block. If no exception is thrown in the <code>try</code>-block, the <code>catch</code>-block is skipped.</p>
<p>The <code>finally</code>-block will always execute after the <code>try</code>-block and <code>catch</code>-block(s) have finished executing. It always executes, regardless of whether an exception was thrown or caught.</p>
<p>You can nest one or more <code>try</code> statements. If an inner <code>try</code> statement does not have a <code>catch</code>-block, the enclosing <code>try</code> statement’s <code>catch</code>-block is used instead.</p>
<p>You can also use the <code>try</code> statement to handle JavaScript exceptions. See the <a href="https://developer.mozilla.org/en-US/docs/Web/JavaScript/Guide">JavaScript Guide</a> for more information on JavaScript exceptions.</p>
<h3 id="unconditional-catch-block">Unconditional catch-block</h3>
<p>When a <code>catch</code>-block is used, the <code>catch</code>-block is executed when any exception is thrown from within the <code>try</code>-block. For example, when the exception occurs in the following code, control transfers to the <code>catch</code>-block.</p>
<pre><code>try {
  throw &#39;myException&#39;; // generates an exception
} catch (e) {
  // statements to handle any exceptions
  logMyErrors(e); // pass exception object to error handler
}</code></pre>
<p>The <code>catch</code>-block specifies an identifier (<code>e</code> in the example above) that holds the value of the exception; this value is only available in the <a href="https://developer.mozilla.org/en-US/docs/Glossary/Scope">scope</a> of the <code>catch</code>-block.</p>
<h3 id="conditional-catch-blocks">Conditional catch-blocks</h3>
<p>You can create "Conditional <code>catch</code>-blocks” by combining <code>try...catch</code> blocks with <code>if...else if...else</code> structures, like this:</p>
<pre><code>try {
  myroutine(); // may throw three types of exceptions
} catch (e) {
  if (e instanceof TypeError) {
    // statements to handle TypeError exceptions
  } else if (e instanceof RangeError) {
    // statements to handle RangeError exceptions
  } else if (e instanceof EvalError) {
    // statements to handle EvalError exceptions
  } else {
    // statements to handle any unspecified exceptions
    logMyErrors(e); // pass exception object to error handler
  }
}</code></pre>
<p>A common use case for this is to only catch (and silence) a small subset of expected errors, and then re-throw the error in other cases:</p>
<pre><code>try {
  myRoutine();
} catch (e) {
  if (e instanceof RangeError) {
    // statements to handle this very common expected error
  } else {
    throw e;  // re-throw the error unchanged
  }
}</code></pre>
<h3 id="the-exception-identifier">The exception identifier</h3>
<p>When an exception is thrown in the <code>try</code>-block, <em><code>exception_var</code></em> (i.e., the <code>e</code> in <code>catch (e)</code>) holds the exception value. You can use this identifier to get information about the exception that was thrown. This identifier is only available in the <code>catch</code>-block’s <a href="https://developer.mozilla.org/en-US/docs/Glossary/Scope">scope</a>. If you don’t need the exception value, it could be omitted.</p>
<pre><code>function isValidJSON(text) {
  try {
    JSON.parse(text);
    return true;
  } catch {
    return false;
  }
}</code></pre>
<h3 id="the-finally-block">The finally-block</h3>
<p>The <code>finally</code>-block contains statements to execute after the <code>try</code>-block and <code>catch</code>-block(s) execute, but before the statements following the <code>try...catch...finally</code>-block. Note that the <code>finally</code>-block executes regardless of whether an exception is thrown. Also, if an exception is thrown, the statements in the <code>finally</code>-block execute even if no <code>catch</code>-block handles the exception.</p>
<p>The following example shows one use case for the <code>finally</code>-block. The code opens a file and then executes statements that use the file; the <code>finally</code>-block makes sure the file always closes after it is used even if an exception was thrown.</p>
<pre><code>openMyFile();
try {
  // tie up a resource
  writeMyFile(theData);
} finally {
  closeMyFile(); // always close the resource
}</code></pre>
<h2 id="examples">Examples</h2>
<h3 id="nested-try-blocks">Nested try-blocks</h3>
<p>First, let’s see what happens with this:</p>
<pre><code>try {
  try {
    throw new Error(&#39;oops&#39;);
  } finally {
    console.log(&#39;finally&#39;);
  }
} catch (ex) {
  console.error(&#39;outer&#39;, ex.message);
}

// Output:
// &quot;finally&quot;
// &quot;outer&quot; &quot;oops&quot;</code></pre>
<p>Now, if we already caught the exception in the inner <code>try</code>-block by adding a <code>catch</code>-block</p>
<pre><code>try {
  try {
    throw new Error(&#39;oops&#39;);
  } catch (ex) {
    console.error(&#39;inner&#39;, ex.message);
  } finally {
    console.log(&#39;finally&#39;);
  }
} catch (ex) {
  console.error(&#39;outer&#39;, ex.message);
}

// Output:
// &quot;inner&quot; &quot;oops&quot;
// &quot;finally&quot;</code></pre>
<p>And now, let’s rethrow the error.</p>
<pre><code>try {
  try {
    throw new Error(&#39;oops&#39;);
  } catch (ex) {
    console.error(&#39;inner&#39;, ex.message);
    throw ex;
  } finally {
    console.log(&#39;finally&#39;);
  }
} catch (ex) {
  console.error(&#39;outer&#39;, ex.message);
}

// Output:
// &quot;inner&quot; &quot;oops&quot;
// &quot;finally&quot;
// &quot;outer&quot; &quot;oops&quot;</code></pre>
<p>Any given exception will be caught only once by the nearest enclosing <code>catch</code>-block unless it is rethrown. Of course, any new exceptions raised in the "inner” block (because the code in <code>catch</code>-block may do something that throws), will be caught by the "outer” block.</p>
<h3 id="returning-from-a-finally-block">Returning from a finally-block</h3>
<p>If the <code>finally</code>-block returns a value, this value becomes the return value of the entire <code>try-catch-finally</code> statement, regardless of any <code>return</code> statements in the <code>try</code> and <code>catch</code>-blocks. This includes exceptions thrown inside of the <code>catch</code>-block:</p>
<pre><code>(function() {
  try {
    try {
      throw new Error(&#39;oops&#39;);
    } catch (ex) {
      console.error(&#39;inner&#39;, ex.message);
      throw ex;
    } finally {
      console.log(&#39;finally&#39;);
      return;
    }
  } catch (ex) {
    console.error(&#39;outer&#39;, ex.message);
  }
})();

// Output:
// &quot;inner&quot; &quot;oops&quot;
// &quot;finally&quot;</code></pre>
<p>The outer "oops” is not thrown because of the return in the <code>finally</code>-block. The same would apply to any value returned from the <code>catch</code>-block.</p>
<h2 id="specifications">Specifications</h2>
<table>
<thead>
<tr class="header">
<th>
Specification
</th>
</tr>
</thead>
<tbody>
<tr class="odd">
<td>
<p><a href="https://tc39.es/ecma262/#sec-try-statement">ECMAScript (ECMA-262) <br/></p>
<span class="small">The definition of ‘try statement’ in that specification.</span></a>
</td>
</tr>
</tbody>
</table>
<h2 id="browser-compatibility">Browser compatibility</h2>
<p>Desktop</p>
<p>Mobile</p>
<p>Chrome</p>
<p>Edge</p>
<p>Firefox</p>
<p>Internet Explorer</p>
<p>Opera</p>
<p>Safari</p>
<p>WebView Android</p>
<p>Chrome Android</p>
<p>Firefox for Android</p>
<p>Opera Android</p>
<p>Safari on IOS</p>
<p>Samsung Internet</p>
<p><code>try...catch</code></p>
<p>1</p>
<p>12</p>
<p>1</p>
<p>5</p>
<p>4</p>
<p>1</p>
<p>1</p>
<p>18</p>
<p>4</p>
<p>10.1</p>
<p>1</p>
<p>1.0</p>
<p><code>optional_catch_binding</code></p>
<p>66</p>
<p>79</p>
<p>58</p>
<p>No</p>
<p>53</p>
<p>11.1</p>
<p>66</p>
<p>66</p>
<p>58</p>
<p>47</p>
<p>11.3</p>
<p>9.0</p>
<h2 id="see-also">See also</h2>
<ul>
<li><a href="../global_objects/error"><code>Error</code></a></li>
<li><a href="throw"><code>throw</code></a></li>
</ul>
<p>Licensed under the Creative Commons Attribution-ShareAlike License v2.5 or later.<br />
<a href="https://developer.mozilla.org/en-US/docs/Web/JavaScript/Reference/Statements/try...catch" class="_attribution-link">https://developer.mozilla.org/en-US/docs/Web/JavaScript/Reference/Statements/try…catch</a></p>
</body>
</html>
